[2023-07-22T01:27:23.845+0000] {taskinstance.py:1103} INFO - Dependencies all met for dep_context=non-requeueable deps ti=<TaskInstance: ETL_toll_data.unzip_data scheduled__2023-07-21T00:00:00+00:00 [queued]>
[2023-07-22T01:27:23.852+0000] {taskinstance.py:1103} INFO - Dependencies all met for dep_context=requeueable deps ti=<TaskInstance: ETL_toll_data.unzip_data scheduled__2023-07-21T00:00:00+00:00 [queued]>
[2023-07-22T01:27:23.853+0000] {taskinstance.py:1308} INFO - Starting attempt 2 of 2
[2023-07-22T01:27:23.864+0000] {taskinstance.py:1327} INFO - Executing <Task(BashOperator): unzip_data> on 2023-07-21 00:00:00+00:00
[2023-07-22T01:27:23.869+0000] {standard_task_runner.py:57} INFO - Started process 855 to run task
[2023-07-22T01:27:23.873+0000] {standard_task_runner.py:84} INFO - Running: ['***', 'tasks', 'run', 'ETL_toll_data', 'unzip_data', 'scheduled__2023-07-21T00:00:00+00:00', '--job-id', '1126', '--raw', '--subdir', 'DAGS_FOLDER/asm08/asm_dag.py', '--cfg-path', '/tmp/tmpm61uv3qy']
[2023-07-22T01:27:23.877+0000] {standard_task_runner.py:85} INFO - Job 1126: Subtask unzip_data
[2023-07-22T01:27:23.951+0000] {task_command.py:410} INFO - Running <TaskInstance: ETL_toll_data.unzip_data scheduled__2023-07-21T00:00:00+00:00 [running]> on host 70d871733d27
[2023-07-22T01:27:24.040+0000] {taskinstance.py:1547} INFO - Exporting env vars: AIRFLOW_CTX_DAG_EMAIL='ngohongthai.uet@gmail.com' AIRFLOW_CTX_DAG_OWNER='Hong Thai Ngo' AIRFLOW_CTX_DAG_ID='ETL_toll_data' AIRFLOW_CTX_TASK_ID='unzip_data' AIRFLOW_CTX_EXECUTION_DATE='2023-07-21T00:00:00+00:00' AIRFLOW_CTX_TRY_NUMBER='2' AIRFLOW_CTX_DAG_RUN_ID='scheduled__2023-07-21T00:00:00+00:00'
[2023-07-22T01:27:24.042+0000] {subprocess.py:63} INFO - Tmp dir root location: /tmp
[2023-07-22T01:27:24.043+0000] {subprocess.py:75} INFO - Running command: ['/bin/bash', '-c', 'tar -zxf /opt/***/dags/asm08/tolldata.tgz']
[2023-07-22T01:27:24.054+0000] {subprocess.py:86} INFO - Output:
[2023-07-22T01:27:24.060+0000] {subprocess.py:93} INFO - tar (child): /opt/***/dags/asm08/tolldata.tgz: Cannot open: No such file or directory
[2023-07-22T01:27:24.061+0000] {subprocess.py:93} INFO - tar (child): Error is not recoverable: exiting now
[2023-07-22T01:27:24.061+0000] {subprocess.py:93} INFO - tar: Child returned status 2
[2023-07-22T01:27:24.061+0000] {subprocess.py:93} INFO - tar: Error is not recoverable: exiting now
[2023-07-22T01:27:24.062+0000] {subprocess.py:97} INFO - Command exited with return code 2
[2023-07-22T01:27:24.075+0000] {taskinstance.py:1824} ERROR - Task failed with exception
Traceback (most recent call last):
  File "/home/airflow/.local/lib/python3.7/site-packages/airflow/operators/bash.py", line 211, in execute
    f"Bash command failed. The command returned a non-zero exit code {result.exit_code}."
airflow.exceptions.AirflowException: Bash command failed. The command returned a non-zero exit code 2.
[2023-07-22T01:27:24.078+0000] {taskinstance.py:1350} INFO - Marking task as FAILED. dag_id=ETL_toll_data, task_id=unzip_data, execution_date=20230721T000000, start_date=20230722T012723, end_date=20230722T012724
[2023-07-22T01:27:24.096+0000] {warnings.py:110} WARNING - /home/***/.local/lib/python3.7/site-packages/***/utils/email.py:153: RemovedInAirflow3Warning: Fetching SMTP credentials from configuration variables will be deprecated in a future release. Please set credentials using a connection instead.
  send_mime_email(e_from=mail_from, e_to=recipients, mime_msg=msg, conn_id=conn_id, dryrun=dryrun)

[2023-07-22T01:27:24.100+0000] {configuration.py:673} WARNING - section/key [smtp/smtp_user] not found in config
[2023-07-22T01:27:24.103+0000] {email.py:269} INFO - Email alerting: attempt 1
[2023-07-22T01:27:24.115+0000] {configuration.py:673} WARNING - section/key [smtp/smtp_user] not found in config
[2023-07-22T01:27:24.118+0000] {email.py:269} INFO - Email alerting: attempt 1
[2023-07-22T01:27:24.119+0000] {taskinstance.py:1889} ERROR - Failed to send email to: ['ngohongthai.uet@gmail.com']
Traceback (most recent call last):
  File "/home/airflow/.local/lib/python3.7/site-packages/airflow/models/taskinstance.py", line 1407, in _run_raw_task
    self._execute_task_with_callbacks(context, test_mode)
  File "/home/airflow/.local/lib/python3.7/site-packages/airflow/models/taskinstance.py", line 1558, in _execute_task_with_callbacks
    result = self._execute_task(context, task_orig)
  File "/home/airflow/.local/lib/python3.7/site-packages/airflow/models/taskinstance.py", line 1628, in _execute_task
    result = execute_callable(context=context)
  File "/home/airflow/.local/lib/python3.7/site-packages/airflow/operators/bash.py", line 211, in execute
    f"Bash command failed. The command returned a non-zero exit code {result.exit_code}."
airflow.exceptions.AirflowException: Bash command failed. The command returned a non-zero exit code 2.

During handling of the above exception, another exception occurred:

Traceback (most recent call last):
  File "/home/airflow/.local/lib/python3.7/site-packages/airflow/models/taskinstance.py", line 2295, in email_alert
    send_email(task.email, subject, html_content)
  File "/home/airflow/.local/lib/python3.7/site-packages/airflow/utils/email.py", line 92, in send_email
    **kwargs,
  File "/home/airflow/.local/lib/python3.7/site-packages/airflow/utils/email.py", line 153, in send_email_smtp
    send_mime_email(e_from=mail_from, e_to=recipients, mime_msg=msg, conn_id=conn_id, dryrun=dryrun)
  File "/home/airflow/.local/lib/python3.7/site-packages/airflow/utils/email.py", line 271, in send_mime_email
    smtp_conn = _get_smtp_connection(smtp_host, smtp_port, smtp_timeout, smtp_ssl)
  File "/home/airflow/.local/lib/python3.7/site-packages/airflow/utils/email.py", line 318, in _get_smtp_connection
    else smtplib.SMTP(host=host, port=port, timeout=timeout)
  File "/usr/local/lib/python3.7/smtplib.py", line 251, in __init__
    (code, msg) = self.connect(host, port)
  File "/usr/local/lib/python3.7/smtplib.py", line 336, in connect
    self.sock = self._get_socket(host, port, self.timeout)
  File "/usr/local/lib/python3.7/smtplib.py", line 307, in _get_socket
    self.source_address)
  File "/usr/local/lib/python3.7/socket.py", line 728, in create_connection
    raise err
  File "/usr/local/lib/python3.7/socket.py", line 716, in create_connection
    sock.connect(sa)
OSError: [Errno 99] Cannot assign requested address

During handling of the above exception, another exception occurred:

Traceback (most recent call last):
  File "/home/airflow/.local/lib/python3.7/site-packages/airflow/models/taskinstance.py", line 1887, in handle_failure
    self.email_alert(error, task)
  File "/home/airflow/.local/lib/python3.7/site-packages/airflow/models/taskinstance.py", line 2297, in email_alert
    send_email(task.email, subject, html_content_err)
  File "/home/airflow/.local/lib/python3.7/site-packages/airflow/utils/email.py", line 92, in send_email
    **kwargs,
  File "/home/airflow/.local/lib/python3.7/site-packages/airflow/utils/email.py", line 153, in send_email_smtp
    send_mime_email(e_from=mail_from, e_to=recipients, mime_msg=msg, conn_id=conn_id, dryrun=dryrun)
  File "/home/airflow/.local/lib/python3.7/site-packages/airflow/utils/email.py", line 271, in send_mime_email
    smtp_conn = _get_smtp_connection(smtp_host, smtp_port, smtp_timeout, smtp_ssl)
  File "/home/airflow/.local/lib/python3.7/site-packages/airflow/utils/email.py", line 318, in _get_smtp_connection
    else smtplib.SMTP(host=host, port=port, timeout=timeout)
  File "/usr/local/lib/python3.7/smtplib.py", line 251, in __init__
    (code, msg) = self.connect(host, port)
  File "/usr/local/lib/python3.7/smtplib.py", line 336, in connect
    self.sock = self._get_socket(host, port, self.timeout)
  File "/usr/local/lib/python3.7/smtplib.py", line 307, in _get_socket
    self.source_address)
  File "/usr/local/lib/python3.7/socket.py", line 728, in create_connection
    raise err
  File "/usr/local/lib/python3.7/socket.py", line 716, in create_connection
    sock.connect(sa)
OSError: [Errno 99] Cannot assign requested address
[2023-07-22T01:27:24.133+0000] {standard_task_runner.py:109} ERROR - Failed to execute job 1126 for task unzip_data (Bash command failed. The command returned a non-zero exit code 2.; 855)
[2023-07-22T01:27:24.170+0000] {local_task_job_runner.py:225} INFO - Task exited with return code 1
[2023-07-22T01:27:24.194+0000] {taskinstance.py:2653} INFO - 0 downstream tasks scheduled from follow-on schedule check
